<?xml version="1.0" ?>
<!--for more instruction about urdf, please refer to http://wiki.ros.org/urdf/XML and http://gazebosim.org/tutorials/?tut=ros_urdf -->
<!-- created manually by Peixuan Shu, just for gazebo_ros_control plugin in rover.sdf to work-->
<robot name="ackerman_car">

  <link name="base_link">
  </link>
  <link name="front_left_wheel_steering_block">
  </link>
  <link name="front_right_wheel_steering_block">
  </link>
  <link name="front_left_wheel">
  </link>
  <link name="front_right_wheel">
  </link>
  <link name="rear_left_wheel">
  </link>
  <link name="rear_right_wheel">
  </link>

  <joint name="front_left_steering_joint" type="revolute">
    <parent link="base_link"/>
    <child link="front_left_wheel_steering_block"/>
    <!--origin rpy="0 0 0" xyz="0 0 0"/>
    <axis xyz="0 0 1"/-->
    <limit effort="1000.0" lower="-0.7727" upper="0.7727" velocity="100.0"/>
    <!-- limit the max effort(N*m) and angle(rad) and velocity(rad/s) of this joint-->
  </joint>

  <joint name="front_right_steering_joint" type="revolute">
    <parent link="base_link"/>
    <child link="front_right_wheel_steering_block"/>
    <!--origin rpy="0 0 0" xyz="0 0 0"/>
    <axis xyz="0 0 1"/-->
    <limit effort="1000.0" lower="-0.7727" upper="0.7727" velocity="100.0"/>
    <!-- limit the max effort(N*m) and angle(rad) and velocity(rad/s) of this joint-->
  </joint>

  <joint name="front_left_wheel_joint" type="continuous">
    <parent link="front_left_wheel_steering_block"/>
    <child link="front_left_wheel"/>
    <!--origin rpy="0 0 0" xyz="0 0 0"/>
    <axis xyz="0 0 1"/-->
    <limit effort="10000.0" velocity="100.0"/>
    <!-- limit the max effort(N*m) and angle(rad) and velocity(rad/s) of this joint-->
    <!-- the radius of wheel is 0.3175m-->
  </joint>

  <joint name="front_right_wheel_joint" type="continuous">
    <parent link="front_right_wheel_steering_block"/>
    <child link="front_right_wheel"/>
    <!--origin rpy="0 0 0" xyz="0 0 0"/>
    <axis xyz="0 0 1"/-->
    <limit effort="10000.0" velocity="100.0"/>
    <!-- limit the max effort(N*m) and angle(rad) and velocity(rad/s) of this joint-->
    <!-- the radius of wheel is 0.3175m-->
  </joint>

  <joint name="rear_left_wheel_joint" type="continuous">
    <parent link="base_link"/>
    <child link="rear_left_wheel"/>
    <!--origin rpy="0 0 0" xyz="0 0 0"/>
    <axis xyz="0 0 1"/-->
    <limit effort="10000.0" velocity="100.0"/>
    <!-- limit the max effort(N*m) and angle(rad) and velocity(rad/s) of this joint-->
    <!-- the radius of wheel is 0.3175m-->
  </joint>

  <joint name="rear_right_wheel_joint" type="continuous">
    <parent link="base_link"/>
    <child link="rear_right_wheel"/>
    <!--origin rpy="0 0 0" xyz="0 0 0"/>
    <axis xyz="0 0 1"/-->
    <limit effort="10000.0" velocity="100.0"/>
    <!-- limit the max effort(N*m) and angle(rad) and velocity(rad/s) of this joint-->
    <!-- the radius of wheel is 0.3175m-->
  </joint>

  <transmission name="front_left_steering_trans">
    <type>transmission_interface/SimpleTransmission</type>
    <joint name="front_left_steering_joint">
      <hardwareInterface>hardware_interface/EffortJointInterface</hardwareInterface>
    </joint>
    <actuator name="front_left_steering_motor">
      <hardwareInterface>hardware_interface/EffortJointInterface</hardwareInterface>
      <mechanicalReduction>1</mechanicalReduction>
    </actuator>
  </transmission>

  <transmission name="front_right_steering_trans">
    <type>transmission_interface/SimpleTransmission</type>
    <joint name="front_right_steering_joint">
      <hardwareInterface>hardware_interface/EffortJointInterface</hardwareInterface>
    </joint>
    <actuator name="front_right_steering_motor">
      <hardwareInterface>hardware_interface/EffortJointInterface</hardwareInterface>
      <mechanicalReduction>1</mechanicalReduction>
    </actuator>
  </transmission>

  <transmission name="front_left_wheel_trans">
    <type>transmission_interface/SimpleTransmission</type>
    <joint name="front_left_wheel_joint">
      <hardwareInterface>hardware_interface/EffortJointInterface</hardwareInterface>
    </joint>
    <actuator name="front_left_wheel_motor">
      <hardwareInterface>hardware_interface/EffortJointInterface</hardwareInterface>
      <mechanicalReduction>1</mechanicalReduction>
    </actuator>
  </transmission>

  <transmission name="front_right_wheel_trans">
    <type>transmission_interface/SimpleTransmission</type>
    <joint name="front_right_wheel_joint">
      <hardwareInterface>hardware_interface/EffortJointInterface</hardwareInterface>
    </joint>
    <actuator name="front_right_wheel_motor">
      <hardwareInterface>hardware_interface/EffortJointInterface</hardwareInterface>
      <mechanicalReduction>1</mechanicalReduction>
    </actuator>
  </transmission>

  <transmission name="rear_left_wheel_trans">
    <type>transmission_interface/SimpleTransmission</type>
    <joint name="rear_left_wheel_joint">
      <hardwareInterface>hardware_interface/EffortJointInterface</hardwareInterface>
    </joint>
    <actuator name="rear_left_wheel_motor">
      <hardwareInterface>hardware_interface/EffortJointInterface</hardwareInterface>
      <mechanicalReduction>1</mechanicalReduction>
    </actuator>
  </transmission>

  <transmission name="rear_right_wheel_trans">
    <type>transmission_interface/SimpleTransmission</type>
    <joint name="rear_right_wheel_joint">
      <hardwareInterface>hardware_interface/EffortJointInterface</hardwareInterface>
    </joint>
    <actuator name="rear_right_wheel_motor">
      <hardwareInterface>hardware_interface/EffortJointInterface</hardwareInterface>
      <mechanicalReduction>1</mechanicalReduction>
    </actuator>
  </transmission>

</robot>
